Workbook

Sheet Overview
A1: CAMPAIGN BUDGET PLANNER | Student Template
A2: Complete all yellow cells. Formulas are pre-built - do not edit black cells.
A4: STEP 1 - CAMPAIGN DETAILS
A5: Campaign Name: | B5: e.g. Summer Launch 2025 | G5: Client / Brand: | H5: e.g. Acme Sports Ltd
A6: Campaign Start: | B6: DD/MM/YYYY | G6: Campaign End: | H6: DD/MM/YYYY
A7: Student Name(s): | B7: Full name(s) of all group members | G7: Student ID(s): | H7: e.g. 1234567, 7654321
A9: STEP 2 - SET YOUR TOTAL CAMPAIGN BUDGET
A10: TOTAL CAMPAIGN BUDGET (£):
A11: Enter your total budget in cell E10 (above). This figure will be used automatically across all sheets.
A13: STEP 3 - BUDGET HEALTH CHECK (auto-calculated from Budget Planner)
A14: Total Campaign Budget: | E14: =Overview!E10 -> 0
A15: Total Budget Allocated: | E15: =IFERROR('Budget Planner'!I26,0) -> 0
A16: Total Budget Remaining: | E16: =IFERROR(Overview!E10-'Budget Planner'!I26,0) -> 0
A17: % of Budget Allocated: | E17: =IFERROR('Budget Planner'!I26/Overview!E10,0) -> 0
A18: WARNING: If the 'Total Budget Remaining' above is negative, you are OVER budget. Return to the Budget Planner and reduce your spend.
A20: HOW TO USE THIS TEMPLATE
A21: STEP 1 | B21: Fill in your Campaign Details above (rows 5-7). Use the yellow cells only.
A22: STEP 2 | B22: Enter your Total Campaign Budget in cell E10. This could be set by your brief or lecturer.
A23: STEP 3 | B23: Go to the 'Budget Planner' tab. Enter how much you plan to spend on each tactic each month. Only fill in the yellow cells - totals are calculated automatically.
A24: STEP 4 | B24: Use the 'Cost Guide' tab to look up typical industry costs for different channels (e.g. how much a Facebook CPM costs, or an influencer post). Use these to justify your budget decisions.
A25: STEP 5 | B25: Go to the 'ROI Calculator' tab. Fill in your estimated conversion rates and average customer value to project the return on investment for your campaign.
A26: TIP | B26: Always keep a Contingency budget (we recommend 5-10% of total). Campaigns rarely go exactly to plan!
A28: COLOUR CODE LEGEND
A29: Yellow cell / Blue text | B29: Input cell - fill this in yourself
A30: Grey cell / Black text | B30: Formula cell - calculated automatically, do not edit
A31: Green cell / Green text | B31: Summary cell - links data from another sheet
A32: Orange cell / Red text | B32: Warning - action required

Sheet Budget Planner
A1: BUDGET PLANNER | Enter your monthly spend per tactic in the yellow cells
A2: Total Budget: | B2: =Overview!$E$10 -> 0 | C2: =IFERROR(I26,0) -> 0 | E2: =IFERROR(Overview!E10-I26,0) -> 0 | G2: =IFERROR(I26/Overview!E10,0) -> 0
A3: HOW TO USE: (1) Rename "Month 1", "Month 2" etc. in row 6 to your actual campaign months. (2) Enter your planned spend (£) for each tactic per month in the YELLOW cells. (3) Totals and percentages are calculated automatically. (4) Only add spend for tactics you are actually using - leave others blank.
A4: COLOUR CODE: Yellow = your inputs (blue text) | Grey = formulas, do not edit (black text) | Blue highlight = totals
A6: Rename months below: | C6: Month 1 | D6: Month 2 | E6: Month 3 | F6: Month 4 | G6: Month 5 | H6: Month 6
A7: Tactic / Activity | B7: Channel | C7: Month 1 | D7: Month 2 | E7: Month 3 | F7: Month 4 | G7: Month 5 | H7: Month 6 | I7: TOTAL SPEND (£) | J7: % of Budget | K7: Notes / Justification
A8: Paid Social - Facebook / Instagram | B8: Social Media | I8: =IFERROR(C8+D8+E8+F8+G8+H8,0) -> 0 | J8: =IFERROR(I8/Overview!$E$10,0) -> 0
A9: Paid Social - TikTok | B9: Social Media | I9: =IFERROR(C9+D9+E9+F9+G9+H9,0) -> 0 | J9: =IFERROR(I9/Overview!$E$10,0) -> 0
A10: Paid Social - LinkedIn | B10: Social Media | I10: =IFERROR(C10+D10+E10+F10+G10+H10,0) -> 0 | J10: =IFERROR(I10/Overview!$E$10,0) -> 0
A11: Paid Social - X (Twitter) | B11: Social Media | I11: =IFERROR(C11+D11+E11+F11+G11+H11,0) -> 0 | J11: =IFERROR(I11/Overview!$E$10,0) -> 0
A12: Google Search Ads (PPC) | B12: Search | I12: =IFERROR(C12+D12+E12+F12+G12+H12,0) -> 0 | J12: =IFERROR(I12/Overview!$E$10,0) -> 0
A13: Google Display Network | B13: Display | I13: =IFERROR(C13+D13+E13+F13+G13+H13,0) -> 0 | J13: =IFERROR(I13/Overview!$E$10,0) -> 0
A14: YouTube Advertising | B14: Video | I14: =IFERROR(C14+D14+E14+F14+G14+H14,0) -> 0 | J14: =IFERROR(I14/Overview!$E$10,0) -> 0
A15: Influencer - Mega (1M+ followers) | B15: Influencer | I15: =IFERROR(C15+D15+E15+F15+G15+H15,0) -> 0 | J15: =IFERROR(I15/Overview!$E$10,0) -> 0
A16: Influencer - Macro (100K - 1M) | B16: Influencer | I16: =IFERROR(C16+D16+E16+F16+G16+H16,0) -> 0 | J16: =IFERROR(I16/Overview!$E$10,0) -> 0
A17: Influencer - Micro (10K - 100K) | B17: Influencer | I17: =IFERROR(C17+D17+E17+F17+G17+H17,0) -> 0 | J17: =IFERROR(I17/Overview!$E$10,0) -> 0
A18: Email Marketing | B18: Direct | I18: =IFERROR(C18+D18+E18+F18+G18+H18,0) -> 0 | J18: =IFERROR(I18/Overview!$E$10,0) -> 0
A19: Content Creation (Photo / Video) | B19: Production | I19: =IFERROR(C19+D19+E19+F19+G19+H19,0) -> 0 | J19: =IFERROR(I19/Overview!$E$10,0) -> 0
... A25: [ADD YOUR OWN TACTIC HERE] | B25: - | I25: =IFERROR(C25+D25+E25+F25+G25+H25,0) -> 0 | J25: =IFERROR(I25/Overview!$E$10,0) -> 0
A26: TOTAL | C26: =IFERROR(SUM(C8:C25),0) -> 0 | D26: =IFERROR(SUM(D8:D25),0) -> 0 | E26: =IFERROR(SUM(E8:E25),0) -> 0 | F26: =IFERROR(SUM(F8:F25),0) -> 0 | G26: =IFERROR(SUM(G8:G25),0) -> 0 | H26: =IFERROR(SUM(H8:H25),0) -> 0 | I26: =IFERROR(SUM(I8:I25),0) -> 0 | J26: =IFERROR(I26/Overview!$E$10,0) -> 0 | K26: Sum of all tactics
A27: REMAINING BUDGET (must be £0 or positive): | I27: =IFERROR(Overview!E10-I26,0) -> 0 | K27: If this is negative, you are over budget!
A28: REMINDER: Use the Cost Guide tab to find average industry costs to inform your spending decisions. Use the Notes column to justify why you allocated budget to each tactic.

Sheet Cost Guide
A1: INDUSTRY AVERAGE COST GUIDE | Use these figures to help plan and justify your budget
A2: These are approximate UK market averages. Actual costs vary depending on targeting, competition, seasonality, and whether you are working with an agency. Use the MID estimate as your default planning figure.
A4: Channel / Platform | B4: Metric | C4: LOW Estimate | D4: MID Estimate (Use this) | E4: HIGH Estimate | F4: Unit | G4: Notes for Students
A5: PAID SOCIAL MEDIA
A6: Facebook / Instagram Ads | B6: CPM | C6: 5 | D6: 9 | E6: 18 | F6: Per 1,000 impressions | G6: Cost to show your ad to 1,000 people
A7: Facebook / Instagram Ads | B7: CPC | C7: 0.4 | D7: 0.85 | E7: 2.5 | F7: Per click | G7: Cost each time someone clicks your ad
A8: Facebook / Instagram Ads | B8: CPL | C8: 5 | D8: 15 | E8: 40 | F8: Per lead | G8: Cost per person who submits a lead form
A9: TikTok Ads | B9: CPM | C9: 4 | D9: 7.5 | E9: 14 | F9: Per 1,000 impressions | G9: Generally lower CPM than Meta for younger audiences
A10: TikTok Ads | B10: CPC | C10: 0.2 | D10: 0.55 | E10: 1.5 | F10: Per click
A11: LinkedIn Ads | B11: CPM | C11: 15 | D11: 28 | E11: 50 | F11: Per 1,000 impressions | G11: Premium B2B platform - higher costs, more professional targeting
A12: LinkedIn Ads | B12: CPC | C12: 3.5 | D12: 7 | E12: 15 | F12: Per click
A13: X (Twitter) Ads | B13: CPM | C13: 4 | D13: 8 | E13: 16 | F13: Per 1,000 impressions
A14: X (Twitter) Ads | B14: CPC | C14: 0.3 | D14: 0.75 | E14: 2 | F14: Per click
A15: SEARCH ADVERTISING
A16: Google Search Ads (PPC) | B16: CPC | C16: 0.5 | D16: 2.5 | E16: 10 | F16: Per click | G16: Varies hugely by keyword competitiveness and industry
A17: Google Search Ads (PPC) | B17: CPL | C17: 15 | D17: 50 | E17: 150 | F17: Per lead | G17: Estimated cost per enquiry/sign-up
A18: DISPLAY & VIDEO
A19: Google Display Network | B19: CPM | C19: 1 | D19: 2.5 | E19: 6 | F19: Per 1,000 impressions | G19: Banner/image ads across websites
A20: YouTube Pre-Roll Ads | B20: CPV | C20: 0.01 | D20: 0.03 | E20: 0.08 | F20: Per view | G20: Only charged when viewer watches 30s or clicks
A21: YouTube Pre-Roll Ads | B21: CPM | C21: 6 | D21: 11 | E21: 22 | F21: Per 1,000 impressions
A22: INFLUENCER MARKETING
A23: Nano Influencer (1K-10K) | B23: Per post | C23: 30 | D23: 150 | E23: 500 | F23: Per sponsored post | G23: High engagement rates, niche audiences
A24: Micro Influencer (10K-100K) | B24: Per post | C24: 100 | D24: 600 | E24: 2000 | F24: Per sponsored post | G24: Good balance of reach and authenticity
A25: Macro Influencer (100K-1M) | B25: Per post | C25: 2000 | D25: 7500 | E25: 20000 | F25: Per sponsored post | G25: Broad reach, less personal engagement
A26: Mega / Celebrity (1M+) | B26: Per post | C26: 20000 | D26: 60000 | E26: 200000 | F26: Per sponsored post | G26: Massive reach but very high cost
A27: NOTE: All tiers - ~50% of post rate
A28: EMAIL MARKETING
A29: Email Platform (e.g. Mailchimp) | B29: Per 1,000 sends | C29: 3 | D29: 10 | E29: 30 | F29: Per 1,000 emails sent | G29: Costs vary by platform and list size
A30: Email Copywriting | B30: Per email | C30: 200 | D30: 500 | E30: 1500 | F30: Per email written | G30: If using a copywriter or agency
A31: PUBLIC RELATIONS (PR)
A32: PR Agency Retainer | B32: Per month | C32: 1500 | D32: 4000 | E32: 10000 | F32: Monthly fee | G32: Smaller boutique agencies at the lower end
A33: Press Release (writing) | B33: Per release | C33: 300 | D33: 700 | E33: 2000 | F33: Per press release | G33: Writing and distribution costs
A34: OUT-OF-HOME (OOH)
A35: 48-sheet Billboard | B35: Per 2 weeks | C35: 400 | D35: 1000 | E35: 2500 | F35: Per 2-week period | G35: Regional vs. city centre locations vary significantly
A36: 6-sheet (Bus Shelter) | B36: Per 2 weeks | C36: 100 | D36: 250 | E36: 600 | F36: Per 2-week period | G36: Local bus shelter panels
A37: Digital OOH Screen | B37: Per 2 weeks | C37: 500 | D37: 1500 | E37: 5000 | F37: Per 2-week period | G37: Digital screens at train stations, shopping centres
A38: RADIO & PODCAST
A39: Radio (30s spot - local) | B39: Per spot | C39: 100 | D39: 400 | E39: 1500 | F39: Per 30-second ad | G39: Regional commercial radio
A40: Radio (30s spot - national) | B40: Per spot | C40: 2000 | D40: 8000 | E40: 30000 | F40: Per 30-second ad | G40: National stations e.g. Absolute Radio
A41: Podcast (host-read ad) | B41: Per episode | C41: 300 | D41: 1500 | E41: 8000 | F41: Per episode | G41: Depends on podcast audience size
...

Sheet ROI Calculator
A1: ROI CALCULATOR | Estimate the return on investment for your campaign
A2: ROI (Return on Investment) = ((Estimated Revenue - Campaign Cost) / Campaign Cost) x 100. This calculator helps you ESTIMATE what your campaign might achieve. For brand awareness channels (OOH, PR, Events), direct ROI is difficult to measure - use the Awareness section below for reach/impressions estimates instead.
A4: KEY ASSUMPTION - Enter once, used across all calculations
A5: Average Customer / Order Value (£):
A6: What is the average amount a customer spends per purchase or the average lifetime value of a new customer? Enter this in cell F5. This figure is used to calculate estimated revenue across all tactics.
A8: SECTION A - PERFORMANCE CHANNELS (Digital channels where direct response / conversions can be estimated)
A9: HOW TO USE: (1) Your budget per tactic is pulled automatically from the Budget Planner. (2) Enter the Cost Per Unit from the Cost Guide (use the MID estimate). (3) Enter your estimated Conversion Rate - what % of people who click/engage actually buy/sign up? (4) All other figures are calculated for you.
A10: Tactic | B10: Budget Allocated (from Budget Planner) | C10: Cost Per Unit (£) (from Cost Guide) | D10: Unit Type (CPM / CPC / CPL) | E10: Estimated Units (impressions or clicks) | F10: Avg Industry Conv. Rate % | G10: YOUR Estimated Conv. Rate % | H10: Estimated Conversions | I10: Avg Customer Value (£) | J10: Estimated Revenue (£) | K10: Channel ROI %
A11: Paid Social - FB / Instagram | B11: =IFERROR('Budget Planner'!$I$8,0) -> 0 | D11: CPC | E11: =IFERROR(IF(B11=0,0,IF(C11=0,0,B11/C11)),0) -> 0 | F11: 2.0% | H11: =IFERROR(IF(G11=0,0,E11*G11),0) -> 0 | I11: =IFERROR($F$5,0) -> 0 | J11: =IFERROR(H11*I11,0) -> 0 | K11: =IFERROR(IF(B11=0,0,(J11-B11)/B11),0) -> 0
A12: Paid Social - TikTok | B12: =IFERROR('Budget Planner'!$I$9,0) -> 0 | D12: CPC | E12: =IFERROR(IF(B12=0,0,IF(C12=0,0,B12/C12)),0) -> 0 | F12: 1.5% | H12: =IFERROR(IF(G12=0,0,E12*G12),0) -> 0 | I12: =IFERROR($F$5,0) -> 0 | J12: =IFERROR(H12*I12,0) -> 0 | K12: =IFERROR(IF(B12=0,0,(J12-B12)/B12),0) -> 0
A13: Paid Social - LinkedIn | B13: =IFERROR('Budget Planner'!$I$10,0) -> 0 | D13: CPC | E13: =IFERROR(IF(B13=0,0,IF(C13=0,0,B13/C13)),0) -> 0 | F13: 1.0% | H13: =IFERROR(IF(G13=0,0,E13*G13),0) -> 0 | I13: =IFERROR($F$5,0) -> 0 | J13: =IFERROR(H13*I13,0) -> 0 | K13: =IFERROR(IF(B13=0,0,(J13-B13)/B13),0) -> 0
A14: Google Search Ads (PPC) | B14: =IFERROR('Budget Planner'!$I$12,0) -> 0 | D14: CPC | E14: =IFERROR(IF(B14=0,0,IF(C14=0,0,B14/C14)),0) -> 0 | F14: 4.0% | H14: =IFERROR(IF(G14=0,0,E14*G14),0) -> 0 | I14: =IFERROR($F$5,0) -> 0 | J14: =IFERROR(H14*I14,0) -> 0 | K14: =IFERROR(IF(B14=0,0,(J14-B14)/B14),0) -> 0
A15: Google Display Network | B15: =IFERROR('Budget Planner'!$I$13,0) -> 0 | D15: CPM | E15: =IFERROR(IF(B15=0,0,IF(C15=0,0,B15/C15)),0) -> 0 | F15: 0.5% | H15: =IFERROR(IF(G15=0,0,E15*G15),0) -> 0 | I15: =IFERROR($F$5,0) -> 0 | J15: =IFERROR(H15*I15,0) -> 0 | K15: =IFERROR(IF(B15=0,0,(J15-B15)/B15),0) -> 0
A16: YouTube Advertising | B16: =IFERROR('Budget Planner'!$I$14,0) -> 0 | D16: CPV | E16: =IFERROR(IF(B16=0,0,IF(C16=0,0,B16/C16)),0) -> 0 | F16: 1.0% | H16: =IFERROR(IF(G16=0,0,E16*G16),0) -> 0 | I16: =IFERROR($F$5,0) -> 0 | J16: =IFERROR(H16*I16,0) -> 0 | K16: =IFERROR(IF(B16=0,0,(J16-B16)/B16),0) -> 0
A17: Influencer - Macro (100K-1M) | B17: =IFERROR('Budget Planner'!$I$16,0) -> 0 | D17: Per Post | E17: =IFERROR(IF(B17=0,0,IF(C17=0,0,B17/C17)),0) -> 0 | F17: 2.5% | H17: =IFERROR(IF(G17=0,0,E17*G17),0) -> 0 | I17: =IFERROR($F$5,0) -> 0 | J17: =IFERROR(H17*I17,0) -> 0 | K17: =IFERROR(IF(B17=0,0,(J17-B17)/B17),0) -> 0
A18: Influencer - Micro (10K-100K) | B18: =IFERROR('Budget Planner'!$I$17,0) -> 0 | D18: Per Post | E18: =IFERROR(IF(B18=0,0,IF(C18=0,0,B18/C18)),0) -> 0 | F18: 3.5% | H18: =IFERROR(IF(G18=0,0,E18*G18),0) -> 0 | I18: =IFERROR($F$5,0) -> 0 | J18: =IFERROR(H18*I18,0) -> 0 | K18: =IFERROR(IF(B18=0,0,(J18-B18)/B18),0) -> 0
A19: Email Marketing | B19: =IFERROR('Budget Planner'!$I$18,0) -> 0 | D19: Per Send | E19: =IFERROR(IF(B19=0,0,IF(C19=0,0,B19/C19)),0) -> 0 | F19: 3.0% | H19: =IFERROR(IF(G19=0,0,E19*G19),0) -> 0 | I19: =IFERROR($F$5,0) -> 0 | J19: =IFERROR(H19*I19,0) -> 0 | K19: =IFERROR(IF(B19=0,0,(J19-B19)/B19),0) -> 0
A20: PERFORMANCE CHANNEL TOTALS | B20: =IFERROR(SUM(B11:B19),0) -> 0 | H20: =IFERROR(SUM(H11:H19),0) -> 0 | J20: =IFERROR(SUM(J11:J19),0) -> 0 | K20: =IFERROR(IF(B20=0,0,(J20-B20)/B20),0) -> 0
A22: SECTION B - BRAND AWARENESS CHANNELS (These channels build brand awareness - direct ROI is harder to measure)
A23: For awareness channels, we estimate REACH (how many people might see your campaign). These channels are still valuable - they build brand recognition that supports your performance channels. Do not expect a direct sales ROI from these.
A24: Tactic | B24: Budget Allocated (from Budget Planner) | C24: CPM / Cost Per 1,000 Impressions (£) | D24: Estimated Total Impressions / Reach | E24: Estimated Cost Per Person Reached (£) | F24: Notes on Measurement
A25: Paid Social - X (Twitter) | B25: =IFERROR('Budget Planner'!$I$11,0) -> 0 | C25: 8 | D25: =IFERROR(IF(C25=0,0,(B25/C25)*1000),0) -> 0 | E25: =IFERROR(IF(D25=0,0,B25/D25),0) -> 0 | F25: Estimated reach based on CPM. Check platform analytics for actual reach.
A26: Influencer - Mega (1M+) | B26: =IFERROR('Budget Planner'!$I$15,0) -> 0 | C26: N/A - see notes | D26: N/A - see notes | E26: N/A - see notes | F26: Reach depends on influencer follower count. Assume 20-30% of followers see a post.
A27: Content Creation (Photo/Video) | B27: =IFERROR('Budget Planner'!$I$19,0) -> 0 | C27: N/A - see notes | D27: N/A - see notes | E27: N/A - see notes | F27: Content is a cost, not a media buy. Track reach via the channels it is used in.
A28: PR & Media Relations | B28: =IFERROR('Budget Planner'!$I$20,0) -> 0 | C28: N/A - see notes | D28: N/A - see notes | E28: N/A - see notes | F28: Track reach via media coverage. Use OTS (Opportunities to See) as your metric.
A29: OOH / Billboards | B29: =IFERROR('Budget Planner'!$I$21,0) -> 0 | C29: 5 | D29: =IFERROR(IF(C29=0,0,(B29/C29)*1000),0) -> 0 | E29: =IFERROR(IF(D29=0,0,B29/D29),0) -> 0 | F29: Local OOH typically reaches 10,000-100,000 people per 2-week period.
A30: Radio / Podcast | B30: =IFERROR('Budget Planner'!$I$22,0) -> 0 | C30: 4 | D30: =IFERROR(IF(C30=0,0,(B30/C30)*1000),0) -> 0 | E30: =IFERROR(IF(D30=0,0,B30/D30),0) -> 0 | F30: Estimated listeners based on station audience figures.
A31: Events & Experiential | B31: =IFERROR('Budget Planner'!$I$23,0) -> 0 | C31: N/A - see notes | D31: N/A - see notes | E31: N/A - see notes | F31: Track footfall/attendance. Estimated cost per person = total event cost / attendees.
A33: OVERALL CAMPAIGN ROI SUMMARY
A34: Total Campaign Investment (from Budget Planner): | J34: =IFERROR('Budget Planner'!I26,0) -> 0
A35: Total Estimated Revenue (Performance Channels only): | J35: =IFERROR(J20,0) -> 0
A36: Estimated Net Return (Revenue minus Investment): | J36: =IFERROR(J35-J34,0) -> 0
A37: Overall Campaign ROI %: | J37: =IFERROR(IF(J34=0,0,(J35-J34)/J34),0) -> 0
A38: ROAS - Return on Ad Spend (Revenue / Investment): | J38: =IFERROR(IF(J34=0,0,J35/J34),0) -> 0
A40: IMPORTANT NOTE: These are ESTIMATES only. Real campaign ROI depends on many factors including creative quality, audience targeting, seasonality, and competition. A ROAS of 3x-5x is typically considered good for most campaigns. Brand awareness channels (Section B) are not included in the ROI calculation as they support long-term brand building which is harder to quantify.
