Workbook

Sheet Overview
B1: SALESPERSON PLATFORM | Marketing ROI Planner
B2: Complete all yellow cells. Formula cells are pre-built — do not edit grey cells.
B4: STEP 1 — CAMPAIGN DETAILS
B5: Campaign Name: | F5: Platform / Product:
B6: Campaign Start: | F6: Campaign End:
B7: Your Name: | F7: Contact:
B9: STEP 2 — SET YOUR TOTAL MONTHLY AD BUDGET
B10: Total Monthly Ad Budget (£): | F10: This is your spend to recruit salespeople via ads.
B12: STEP 3 — BUDGET HEALTH CHECK (auto-filled from Budget Planner)
B13: Total Monthly Ad Budget: | C13: ='Budget Planner'!E3 -> 0
B14: Total Budget Allocated: | C14: ='Budget Planner'!H26 -> 0
B15: Total Budget Remaining: | C15: ='Budget Planner'!H27 -> 0
B16: % of Budget Allocated: | C16: =IFERROR('Budget Planner'!H26/'Budget Planner'!E3,0) -> 0
B17: ⚠ WARNING: If 'Total Budget Remaining' above is negative you are OVER budget. Return to Budget Planner and reduce spend.
B19: HOW TO USE THIS PLANNER
B20: STEP 1 | C20: Fill in Campaign Details above.
B21: STEP 2 | C21: Enter your Total Monthly Ad Budget in C10.
B22: STEP 3 | C22: Go to Budget Planner — enter monthly spend per ad channel for salesperson recruitment.
B23: STEP 4 | C23: Use the Cost Guide tab for typical CPC / CPM benchmarks per platform.
B24: STEP 5 | C24: Go to ROI Calculator — enter your CPC, app download-to-activation rate, and salesperson close rate to project upfront and recurring revenue from ad spend.
B25: TIP | C25: Keep 5-10% as contingency. The key metric is Cost Per Closed Sale, not just CPC.
B27: COLOUR CODE LEGEND
B28: Yellow cell / Blue text | C28: Input cell — fill this in
B29: Grey cell / Black text | C29: Formula cell — do not edit
B30: Green cell / Green text | C30: Summary — links from another sheet
B31: Orange cell / Red text | C31: Warning — action needed

Sheet Budget Planner
B1: BUDGET PLANNER | Enter monthly ad spend per channel in the yellow cells
B2: HOW TO USE: (1) Rename Month 1–6 to your actual months. (2) Enter planned spend in YELLOW cells. (3) Totals auto-calculate. (4) Channels here are for salesperson recruitment ads — not product ads.
B3: Total Monthly Ad Budget (£): | E3: =Overview!C10 -> 0 | G3: ← pulled from Overview
B4: Rename months → | D4: Month 1 | E4: Month 2 | F4: Month 3 | G4: Month 4 | H4: Month 5 | I4: Month 6
B5: Ad Channel | C5: Category | D5: Month 1 | E5: Month 2 | F5: Month 3 | G5: Month 4 | H5: Month 5 | I5: Month 6 | J5: TOTAL (£) | K5: % of Budget
B6: Facebook / Instagram Ads | C6: Paid Social | J6: =SUM(D6:I6) -> 0 | K6: =IFERROR(J6/Overview!C10,0) -> 0
B7: TikTok Ads | C7: Paid Social | J7: =SUM(D7:I7) -> 0 | K7: =IFERROR(J7/Overview!C10,0) -> 0
B8: LinkedIn Ads | C8: Paid Social | J8: =SUM(D8:I8) -> 0 | K8: =IFERROR(J8/Overview!C10,0) -> 0
B9: Google Search Ads (PPC) | C9: Search | J9: =SUM(D9:I9) -> 0 | K9: =IFERROR(J9/Overview!C10,0) -> 0
B10: Google Display Network | C10: Display | J10: =SUM(D10:I10) -> 0 | K10: =IFERROR(J10/Overview!C10,0) -> 0
B11: YouTube Ads | C11: Video | J11: =SUM(D11:I11) -> 0 | K11: =IFERROR(J11/Overview!C10,0) -> 0
B12: Reddit Ads | C12: Community | J12: =SUM(D12:I12) -> 0 | K12: =IFERROR(J12/Overview!C10,0) -> 0
B13: Contingency / Reserve | C13: Reserve | J13: =SUM(D13:I13) -> 0 | K13: =IFERROR(J13/Overview!C10,0) -> 0
B14: [Add your own channel] | C14: — | J14: =SUM(D14:I14) -> 0 | K14: =IFERROR(J14/Overview!C10,0) -> 0
B15: TOTAL | D15: =SUM(D6:D14) -> 0 | E15: =SUM(E6:E14) -> 0 | F15: =SUM(F6:F14) -> 0 | G15: =SUM(G6:G14) -> 0 | H15: =SUM(H6:H14) -> 0 | I15: =SUM(I6:I14) -> 0 | J15: =SUM(J6:J14) -> 0 | K15: =SUM(K6:K14) -> 0
B16: REMAINING BUDGET (must be £0 or positive): | J16: =Overview!C10-J15 -> 0 | K16: ← If negative, reduce spend!

Sheet Cost Guide
B1: INDUSTRY AVERAGE COST GUIDE | Use these to inform and justify your budget
B2: These are approximate UK 2025-26 averages. Use the MID estimate as your default. Costs vary by targeting, competition, and creative quality.
B3: Channel / Platform | C3: Metric | D3: LOW | E3: MID (use this) | F3: HIGH | G3: Notes
B4: PAID SOCIAL
B5: Facebook / Instagram | C5: CPC | D5: £0.40 | E5: £0.85 | F5: £2.50 | G5: Cost per click — good for side-hustle recruitment creatives
B6: Facebook / Instagram | C6: CPM | D6: £5 | E6: £9 | F6: £18 | G6: Cost per 1,000 impressions
B7: Facebook / Instagram | C7: CPL (App Download) | D7: £0.50 | E7: £1.50 | F7: £4 | G7: Cost per app install / sign-up — lower than CPL for product sales
B8: TikTok Ads | C8: CPC | D8: £0.20 | E8: £0.55 | F8: £1.50 | G8: Underpriced attention for 18-30 demographic
B9: TikTok Ads | C9: CPM | D9: £4 | E9: £7.50 | F9: £14 | G9: Lower CPM than Meta — strong for viral side-hustle content
B10: TikTok Ads | C10: CPL (App Download) | D10: £0.30 | E10: £1.00 | F10: £3 | G10: Potentially cheapest download channel for your demographic
B11: LinkedIn Ads | C11: CPC | D11: £3.50 | E11: £7 | F11: £15 | G11: Higher cost but targets professionals — use for B2B operator recruitment
B12: Reddit Ads | C12: CPC | D12: £0.20 | E12: £0.60 | F12: £2 | G12: r/sidehustle, r/UKPersonalFinance — self-selecting motivated audience
B13: Google Search Ads | C13: CPC | D13: £0.50 | E13: £2.50 | F13: £10 | G13: Use for branded terms once platform is known
B14: Google Display | C14: CPM | D14: £1 | E14: £2.50 | F14: £6 | G14: Retargeting website visitors
B15: YouTube Pre-Roll | C15: CPV | D15: £0.01 | E15: £0.03 | F15: £0.08 | G15: Per view — good for demo of the platform concept
B16: YOUR BUSINESS — KEY CONVERSION BENCHMARKS
B17: App Download → Activation Rate | C17: % of downloads who claim a lead | D17: 10% | E17: 30% | F17: 50% | G17: Key assumption — validate in week 1
B18: Pitch → Close Rate | C18: % of pitches that close | D18: 2% | E18: 5% | F18: 8% | G18: Your most important metric
B19: Salesperson Daily Pitches | C19: Businesses visited per day | D19: 10 | E19: 20 | F19: 30 | G19: Depends on business density and pitch length
B20: Cost Per Closed Sale (from ads) | C20: Ad spend ÷ closes | D20: — | E20: Calculate in ROI tab | F20: — | G20: This is your real PAC from advertising

Sheet ROI Calculator
B1: ROI CALCULATOR | From ad spend → app downloads → salespeople → closed sales
B2: This calculator has two layers: (1) Ad spend → app downloads → activated salespeople. (2) Activated salespeople → pitches → closed sales → revenue. Your ad spend funds recruitment; salespeople fund themselves via commission.
B4: KEY ASSUMPTIONS — Enter once, used across all calculations
B5: Upfront website price charged to client (£): | E5: 350
B6: Monthly recurring charged to client (£): | E6: 27.5
B7: Commission per closed sale (£): | E7: 50
B8: Your net per closed sale after commission (£): | E8: =E5-E7 -> 300
B9: Monthly hosting cost per live site (£): | E9: 2
B10: Net monthly recurring per client (£): | E10: =E6-E9 -> 25.5
B12: SECTION A — Ad Spend → App Downloads → Activated Salespeople
B13: HOW TO USE: Enter your monthly budget per channel, CPC/CPL from Cost Guide, and estimated download-to-activation rate. All other figures calculate automatically.
B14: Ad Channel | C14: Monthly Budget (£) | D14: CPC / CPL (£) | E14: Est. Downloads / Signups | F14: Activation Rate % | G14: Activated Salespeople | H14: Pitches Per Person/Month | I14: Total Pitches/Month
B15: Facebook / Instagram Ads | E15: =IFERROR(C15/D15,0) -> 0 | F15: 0.3 | G15: =IFERROR(ROUND(E15*F15,0),0) -> 0 | H15: 20 | I15: =G15*H15 -> 0
B16: TikTok Ads | E16: =IFERROR(C16/D16,0) -> 0 | F16: 0.3 | G16: =IFERROR(ROUND(E16*F16,0),0) -> 0 | H16: 20 | I16: =G16*H16 -> 0
B17: LinkedIn Ads | E17: =IFERROR(C17/D17,0) -> 0 | F17: 0.3 | G17: =IFERROR(ROUND(E17*F17,0),0) -> 0 | H17: 20 | I17: =G17*H17 -> 0
B18: Reddit Ads | E18: =IFERROR(C18/D18,0) -> 0 | F18: 0.3 | G18: =IFERROR(ROUND(E18*F18,0),0) -> 0 | H18: 20 | I18: =G18*H18 -> 0
B19: Google Search Ads | E19: =IFERROR(C19/D19,0) -> 0 | F19: 0.3 | G19: =IFERROR(ROUND(E19*F19,0),0) -> 0 | H19: 20 | I19: =G19*H19 -> 0
B20: YouTube Ads | E20: =IFERROR(C20/D20,0) -> 0 | F20: 0.3 | G20: =IFERROR(ROUND(E20*F20,0),0) -> 0 | H20: 20 | I20: =G20*H20 -> 0
B21: TOTALS | C21: =SUM(C15:C20) -> 0 | E21: =SUM(E15:E20) -> 0 | G21: =SUM(G15:G20) -> 0 | I21: =SUM(I15:I20) -> 0
B23: SECTION B — Salesperson Pitches → Closed Sales → Revenue
B24: This section takes total pitches from Section A and models revenue. Note: commission costs are paid FROM client payments, not from your ad budget.
B25: Metric | C25: Low Scenario | D25: Realistic Scenario | E25: Optimistic Scenario | F25: Notes
B26: Total Pitches / Month | C26: =I21 -> 0 | D26: =I21 -> 0 | E26: =I21 -> 0 | F26: From Section A totals
B27: Close Rate % | C27: 0.02 | D27: 0.05 | E27: 0.08 | F27: Enter your estimate — validate with real data first
B28: Closed Sales / Month | C28: =ROUND(C26*C27,0) -> 0 | D28: =ROUND(D26*D27,0) -> 0 | E28: =ROUND(E26*E27,0) -> 0 | F28: Pitches × close rate
B29: Gross Upfront Revenue (£) | C29: =C28*E5 -> 0 | D29: =D28*E5 -> 0 | E29: =E28*E5 -> 0 | F29: Closed sales × £350
B30: Total Commission Paid (£) | C30: =C28*E7 -> 0 | D30: =D28*E7 -> 0 | E30: =E28*E7 -> 0 | F30: Closed sales × £50 — paid from client payment
B31: Net Upfront Revenue to You (£) | C31: =C29-C30 -> 0 | D31: =D29-D30 -> 0 | E31: =E29-E30 -> 0 | F31: After commission
B32: New Recurring Clients Added | C32: =C28 -> 0 | D32: =D28 -> 0 | E32: =E28 -> 0 | F32: Equals closed sales
B33: New MRR Added (£) | C33: =C32*E10 -> 0 | D33: =D32*E10 -> 0 | E33: =E32*E10 -> 0 | F33: New clients × net £25.50/month
B34: Cumulative MRR after 6 months (£) | C34: =ROUND(C33*6*(1-0.05^6)/(1-0.05),0) -> 0 | D34: =ROUND(D33*6*(1-0.05^6)/(1-0.05),0) -> 0 | E34: =ROUND(E33*6*(1-0.05^6)/(1-0.05),0) -> 0 | F34: Compound growth with 5% monthly churn
B35: 6-Month Upfront Revenue (£) | C35: =C31*6 -> 0 | D35: =D31*6 -> 0 | E35: =E31*6 -> 0 | F35: Net upfront × 6 months
B36: 6-Month Recurring Revenue (£) | C36: =C34*3 -> 0 | D36: =D34*3 -> 0 | E36: =E34*3 -> 0 | F36: Approximate cumulative recurring
B37: TOTAL 6-MONTH NET REVENUE (£) | C37: =C35+C36 -> 0 | D37: =D35+D36 -> 0 | E37: =E35+E36 -> 0 | F37: Your target: £40,000–£50,000
B39: SECTION C — True Cost Per Closed Sale (Your Real PAC from Ads)
B40: Metric | C40: Low | D40: Realistic | E40: Optimistic | F40: Notes
B41: Monthly Ad Spend (£) | C41: =C21 -> 0 | D41: =I20 -> 0 | E41: =I20 -> 0 | F41: From Section A
B42: Closed Sales / Month | C42: =C28 -> 0 | D42: =D28 -> 0 | E42: =E28 -> 0 | F42: From Section B
B43: Ad Cost Per Closed Sale (£) | C43: =IFERROR(C41/C42,0) -> 0 | D43: =IFERROR(C41/D42,0) -> 0 | E43: =IFERROR(C41/E42,0) -> 0 | F43: Ad spend ÷ closes — your true PAC
B44: Commission Per Closed Sale (£) | C44: =E7 -> 50 | D44: =E7 -> 50 | E44: =E7 -> 50 | F44: Fixed regardless of ad channel
...
